E.......E
======================================================================
ERROR: test_every_three_digit_number (test_numbers.NumbersTest.test_every_three_digit_number)
----------------------------------------------------------------------
Traceback (most recent call last):
  File "/sandbox/test_numbers.py", line 64, in test_every_three_digit_number
    verify(result)
  File "/usr/local/lib/python3.12/site-packages/approvaltests/approvals.py", line 120, in verify
    verify_with_namer(
  File "/usr/local/lib/python3.12/site-packages/approvaltests/approvals.py", line 220, in verify_with_namer
    verify_with_namer_and_writer(namer, writer, options=options)
  File "/usr/local/lib/python3.12/site-packages/approvaltests/approvals.py", line 231, in verify_with_namer_and_writer
    error = FileApprover.verify(namer, writer, options.reporter, options.comparator)
            ^^^^^^^^^^^^^^^^^^^^^^^^^^^^^^^^^^^^^^^^^^^^^^^^^^^^^^^^^^^^^^^^^^^^^^^^
  File "/usr/local/lib/python3.12/site-packages/approvaltests/file_approver.py", line 55, in verify
    verified = FileApprover.verify_files(approved, received, reporter, comparator)
               ^^^^^^^^^^^^^^^^^^^^^^^^^^^^^^^^^^^^^^^^^^^^^^^^^^^^^^^^^^^^^^^^^^^
  File "/usr/local/lib/python3.12/site-packages/approvaltests/file_approver.py", line 111, in verify_files
    raise ReporterNotWorkingException(reporter)
approvaltests.file_approver.ReporterNotWorkingException: Reporter <approvaltests.reporters.report_on_cyber_dojo.ReportOnCyberDojo object at 0x7f7f89b724e0> failed to work!

======================================================================
ERROR: test_three_hundred_ten (test_numbers.NumbersTest.test_three_hundred_ten)
----------------------------------------------------------------------
Traceback (most recent call last):
  File "/sandbox/test_numbers.py", line 60, in test_three_hundred_ten
    verify(result)
  File "/usr/local/lib/python3.12/site-packages/approvaltests/approvals.py", line 120, in verify
    verify_with_namer(
  File "/usr/local/lib/python3.12/site-packages/approvaltests/approvals.py", line 220, in verify_with_namer
    verify_with_namer_and_writer(namer, writer, options=options)
  File "/usr/local/lib/python3.12/site-packages/approvaltests/approvals.py", line 231, in verify_with_namer_and_writer
    error = FileApprover.verify(namer, writer, options.reporter, options.comparator)
            ^^^^^^^^^^^^^^^^^^^^^^^^^^^^^^^^^^^^^^^^^^^^^^^^^^^^^^^^^^^^^^^^^^^^^^^^
  File "/usr/local/lib/python3.12/site-packages/approvaltests/file_approver.py", line 55, in verify
    verified = FileApprover.verify_files(approved, received, reporter, comparator)
               ^^^^^^^^^^^^^^^^^^^^^^^^^^^^^^^^^^^^^^^^^^^^^^^^^^^^^^^^^^^^^^^^^^^
  File "/usr/local/lib/python3.12/site-packages/approvaltests/file_approver.py", line 111, in verify_files
    raise ReporterNotWorkingException(reporter)
approvaltests.file_approver.ReporterNotWorkingException: Reporter <approvaltests.reporters.report_on_cyber_dojo.ReportOnCyberDojo object at 0x7f7f89cf1dc0> failed to work!

----------------------------------------------------------------------
Ran 9 tests in 0.046s

FAILED (errors=2)
