EE.....E
======================================================================
ERROR: test_every_two_digit_number (test_numbers.NumbersTest.test_every_two_digit_number)
----------------------------------------------------------------------
Traceback (most recent call last):
  File "/sandbox/test_numbers.py", line 47, in test_every_two_digit_number
    verify(result)
  File "/usr/local/lib/python3.12/site-packages/approvaltests/approvals.py", line 120, in verify
    verify_with_namer(
  File "/usr/local/lib/python3.12/site-packages/approvaltests/approvals.py", line 220, in verify_with_namer
    verify_with_namer_and_writer(namer, writer, options=options)
  File "/usr/local/lib/python3.12/site-packages/approvaltests/approvals.py", line 231, in verify_with_namer_and_writer
    error = FileApprover.verify(namer, writer, options.reporter, options.comparator)
            ^^^^^^^^^^^^^^^^^^^^^^^^^^^^^^^^^^^^^^^^^^^^^^^^^^^^^^^^^^^^^^^^^^^^^^^^
  File "/usr/local/lib/python3.12/site-packages/approvaltests/file_approver.py", line 55, in verify
    verified = FileApprover.verify_files(approved, received, reporter, comparator)
               ^^^^^^^^^^^^^^^^^^^^^^^^^^^^^^^^^^^^^^^^^^^^^^^^^^^^^^^^^^^^^^^^^^^
  File "/usr/local/lib/python3.12/site-packages/approvaltests/file_approver.py", line 111, in verify_files
    raise ReporterNotWorkingException(reporter)
approvaltests.file_approver.ReporterNotWorkingException: Reporter <approvaltests.reporters.report_on_cyber_dojo.ReportOnCyberDojo object at 0x7f5f514f2450> failed to work!

======================================================================
ERROR: test_ninety_nine (test_numbers.NumbersTest.test_ninety_nine)
----------------------------------------------------------------------
Traceback (most recent call last):
  File "/sandbox/test_numbers.py", line 43, in test_ninety_nine
    verify(result)
  File "/usr/local/lib/python3.12/site-packages/approvaltests/approvals.py", line 120, in verify
    verify_with_namer(
  File "/usr/local/lib/python3.12/site-packages/approvaltests/approvals.py", line 220, in verify_with_namer
    verify_with_namer_and_writer(namer, writer, options=options)
  File "/usr/local/lib/python3.12/site-packages/approvaltests/approvals.py", line 231, in verify_with_namer_and_writer
    error = FileApprover.verify(namer, writer, options.reporter, options.comparator)
            ^^^^^^^^^^^^^^^^^^^^^^^^^^^^^^^^^^^^^^^^^^^^^^^^^^^^^^^^^^^^^^^^^^^^^^^^
  File "/usr/local/lib/python3.12/site-packages/approvaltests/file_approver.py", line 55, in verify
    verified = FileApprover.verify_files(approved, received, reporter, comparator)
               ^^^^^^^^^^^^^^^^^^^^^^^^^^^^^^^^^^^^^^^^^^^^^^^^^^^^^^^^^^^^^^^^^^^
  File "/usr/local/lib/python3.12/site-packages/approvaltests/file_approver.py", line 111, in verify_files
    raise ReporterNotWorkingException(reporter)
approvaltests.file_approver.ReporterNotWorkingException: Reporter <approvaltests.reporters.report_on_cyber_dojo.ReportOnCyberDojo object at 0x7f5f51978c80> failed to work!

======================================================================
ERROR: test_three_hundred_ten (test_numbers.NumbersTest.test_three_hundred_ten)
----------------------------------------------------------------------
Traceback (most recent call last):
  File "/sandbox/test_numbers.py", line 59, in test_three_hundred_ten
    verify(result)
  File "/usr/local/lib/python3.12/site-packages/approvaltests/approvals.py", line 120, in verify
    verify_with_namer(
  File "/usr/local/lib/python3.12/site-packages/approvaltests/approvals.py", line 220, in verify_with_namer
    verify_with_namer_and_writer(namer, writer, options=options)
  File "/usr/local/lib/python3.12/site-packages/approvaltests/approvals.py", line 231, in verify_with_namer_and_writer
    error = FileApprover.verify(namer, writer, options.reporter, options.comparator)
            ^^^^^^^^^^^^^^^^^^^^^^^^^^^^^^^^^^^^^^^^^^^^^^^^^^^^^^^^^^^^^^^^^^^^^^^^
  File "/usr/local/lib/python3.12/site-packages/approvaltests/file_approver.py", line 55, in verify
    verified = FileApprover.verify_files(approved, received, reporter, comparator)
               ^^^^^^^^^^^^^^^^^^^^^^^^^^^^^^^^^^^^^^^^^^^^^^^^^^^^^^^^^^^^^^^^^^^
  File "/usr/local/lib/python3.12/site-packages/approvaltests/file_approver.py", line 111, in verify_files
    raise ReporterNotWorkingException(reporter)
approvaltests.file_approver.ReporterNotWorkingException: Reporter <approvaltests.reporters.report_on_cyber_dojo.ReportOnCyberDojo object at 0x7f5f514f2ed0> failed to work!

----------------------------------------------------------------------
Ran 8 tests in 0.031s

FAILED (errors=3)
